<?xml version="1.0" encoding="utf-8"?>
<!-- This URDF was automatically created by SolidWorks to URDF Exporter! Originally created by Stephen Brawner (brawner@gmail.com) 
     Commit Version: 1.6.0-4-g7f85cfe  Build Version: 1.6.7995.38578
     For more information, please see http://wiki.ros.org/sw_urdf_exporter -->
<robot
  name="EnsamblajeFinal">
  <link
    name="base_link">
    <inertial>
      <origin
        xyz="0.043109 -0.004032 0.036005"
        rpy="0 0 0" />
      <mass
        value="0.75414" />
      <inertia
        ixx="0.0031639"
        ixy="-4.8663E-07"
        ixz="-3.0987E-06"
        iyy="0.00076691"
        iyz="-7.2585E-07"
        izz="0.0035191" />
    </inertial>
    <visual>
      <origin
        xyz="0 0 0"
        rpy="0 0 0" />
      <geometry>
        <mesh
          filename="package://my_robot_description/meshes/base_link.STL" />
      </geometry>
      <material
        name="">
        <color
          rgba="0.6 0.6 0.6 1" />
      </material>
    </visual>
    <collision>
      <origin
        xyz="0 0 0"
        rpy="0 0 0" />
      <geometry>
        <mesh
          filename="package://my_robot_description/meshes/base_link.STL" />
      </geometry>
    </collision>
  </link>
  <link
    name="RightWheel_link">
    <inertial>
      <origin
        xyz="0 6.5052E-19 0.014364"
        rpy="0 0 0" />
      <mass
        value="0.033874" />
      <inertia
        ixx="1.0207E-05"
        ixy="-4.8599E-22"
        ixz="1.3665E-22"
        iyy="1.0207E-05"
        iyz="3.7396E-22"
        izz="1.5582E-05" />
    </inertial>
    <visual>
      <origin
        xyz="0 0 0"
        rpy="0 0 0" />
      <geometry>
        <mesh
          filename="package://my_robot_description/meshes/RightWheel_link.STL" />
      </geometry>
      <material
        name="">
        <color
          rgba="0.79216 0.81961 0.93333 1" />
      </material>
    </visual>
    <collision>
      <origin
        xyz="0 0 0"
        rpy="0 0 0" />
      <geometry>
        <mesh
          filename="package://my_robot_description/meshes/RightWheel_link.STL" />
      </geometry>
    </collision>
  </link>
  <joint
    name="RightWheel_joint"
    type="continuous">
    <origin
      xyz="-0.032064 -0.0865 0.01"
      rpy="-1.5708 0 3.1416" />
    <parent
      link="base_link" />
    <child
      link="RightWheel_link" />
    <axis
      xyz="0 0 1" />
    <limit
      effort="100"
      velocity="100" />
    <dynamics
      damping="0.1"
      friction="0.1" />
  </joint>
  <link
    name="LeftWheel_link">
    <inertial>
      <origin
        xyz="-2.7756E-17 -4.12E-18 -0.014364"
        rpy="0 0 0" />
      <mass
        value="0.033874" />
      <inertia
        ixx="1.0207E-05"
        ixy="-1.4844E-21"
        ixz="-7.666E-22"
        iyy="1.0207E-05"
        iyz="-9.1671E-22"
        izz="1.5582E-05" />
    </inertial>
    <visual>
      <origin
        xyz="0 0 0"
        rpy="0 0 0" />
      <geometry>
        <mesh
          filename="package://my_robot_description/meshes/LeftWheel_link.STL" />
      </geometry>
      <material
        name="">
        <color
          rgba="0.79216 0.81961 0.93333 1" />
      </material>
    </visual>
    <collision>
      <origin
        xyz="0 0 0"
        rpy="0 0 0" />
      <geometry>
        <mesh
          filename="package://my_robot_description/meshes/LeftWheel_link.STL" />
      </geometry>
    </collision>
  </link>
  <joint
    name="LeftWheel_join"
    type="continuous">
    <origin
      xyz="-0.032064 0.0865 0.01"
      rpy="-1.5708 0 3.1416" />
    <parent
      link="base_link" />
    <child
      link="LeftWheel_link" />
    <axis
      xyz="0 0 1" />
    <limit
      effort="100"
      velocity="100" />
    <dynamics
      damping="0.1"
      friction="0.1" />
  </joint>
  <link
    name="BaseCastorWheel_link">
    <inertial>
      <origin
        xyz="1.3878E-17 -1.3878E-17 0.0018589"
        rpy="0 0 0" />
      <mass
        value="0.00081529" />
      <inertia
        ixx="1.8443E-08"
        ixy="-1.8943E-10"
        ixz="-5.6617E-25"
        iyy="1.5593E-08"
        iyz="-1.0819E-24"
        izz="2.5253E-08" />
    </inertial>
    <visual>
      <origin
        xyz="0 0 0"
        rpy="0 0 0" />
      <geometry>
        <mesh
          filename="package://my_robot_description/meshes/BaseCastorWheel_link.STL" />
      </geometry>
      <material
        name="">
        <color
          rgba="0.79216 0.81961 0.93333 1" />
      </material>
    </visual>
    <collision>
      <origin
        xyz="0 0 0"
        rpy="0 0 0" />
      <geometry>
        <mesh
          filename="package://my_robot_description/meshes/BaseCastorWheel_link.STL" />
      </geometry>
    </collision>
  </link>
  <joint
    name="BaseCastorWheel_joint"
    type="continuous">
    <origin
      xyz="0.087786 0 -0.007"
      rpy="3.1416 0 0" />
    <parent
      link="base_link" />
    <child
      link="BaseCastorWheel_link" />
    <axis
      xyz="0 0 1" />
    <limit
      effort="100"
      velocity="100" />
    <dynamics
      damping="0.1"
      friction="0.1" />
  </joint>
  <link
    name="CastorWheel_link">
    <inertial>
      <origin
        xyz="0 3.4694E-18 0"
        rpy="0 0 0" />
      <mass
        value="0.00034636" />
      <inertia
        ixx="2.8214E-09"
        ixy="-1.6919E-25"
        ixz="4.7535E-13"
        iyy="2.8214E-09"
        iyz="2.4566E-26"
        izz="2.8142E-09" />
    </inertial>
    <visual>
      <origin
        xyz="0 0 0"
        rpy="0 0 0" />
      <geometry>
        <mesh
          filename="package://my_robot_description/meshes/CastorWheel_link.STL" />
      </geometry>
      <material
        name="">
        <color
          rgba="0.79216 0.81961 0.93333 1" />
      </material>
    </visual>
    <collision>
      <origin
        xyz="0 0 0"
        rpy="0 0 0" />
      <geometry>
        <mesh
          filename="package://my_robot_description/meshes/CastorWheel_link.STL" />
      </geometry>
    </collision>
  </link>
  <joint
    name="CastorWheel_joint"
    type="continuous">
    <origin
      xyz="0 0 0.007"
      rpy="1.5708 0 0" />
    <parent
      link="BaseCastorWheel_link" />
    <child
      link="CastorWheel_link" />
    <axis
      xyz="0 0 1" />
    <limit
      effort="100"
      velocity="100" />
    <dynamics
      damping="0.1"
      friction="0.1" />
  </joint>
</robot>